<?xml version="1.0" encoding="utf-8"?>
<!-- This URDF was automatically created by SolidWorks to URDF Exporter! Originally created by Stephen Brawner (brawner@gmail.com) 
     Commit Version: 1.6.0-1-g15f4949  Build Version: 1.6.7594.29634
     For more information, please see http://wiki.ros.org/sw_urdf_exporter -->
<robot
  name="TCB610_06N_urdf">
<mujoco>
    <compiler meshdir="../meshes/" discardvisual="false"/>
  </mujoco>
  <link
    name="tl_robot_link0">
    <inertial>
      <origin
        xyz="0.000197158335101408 -5.65942773516878E-05 0.0376676214851066"
        rpy="0 0 0" />
      <mass
        value="0.749899458922545" />
      <inertia
        ixx="0.00156235136176764"
        ixy="-6.48262732748015E-08"
        ixz="4.21713907756751E-05"
        iyy="0.00143055291291807"
        iyz="-1.4740224733695E-07"
        izz="0.00181952433904877" />
    </inertial>
    <visual>
      <origin
        xyz="0 0 0"
        rpy="0 0 0" />
      <geometry>
        <mesh
          filename="package://TCB610_06N_urdf/meshes/tl_robot_link0.STL" />
      </geometry>
      <material
        name="">
        <color
          rgba="0.792156862745098 0.819607843137255 0.933333333333333 1" />
      </material>
    </visual>
    <collision>
      <origin
        xyz="0 0 0"
        rpy="0 0 0" />
      <geometry>
        <mesh
          filename="package://TCB610_06N_urdf/meshes/tl_robot_link0.STL" />
      </geometry>
    </collision>
  </link>
  <link
    name="tl_robot_link1">
    <inertial>
      <origin
        xyz="-3.22169620622034E-06 -0.0151242570890185 0.0705019653501001"
        rpy="0 0 0" />
      <mass
        value="0.518481282081828" />
      <inertia
        ixx="0.00167110041898517"
        ixy="1.56212363051667E-07"
        ixz="-1.54670410912784E-07"
        iyy="0.00175701064773447"
        iyz="0.000263613286475281"
        izz="0.00078448162552415" />
    </inertial>
    <visual>
      <origin
        xyz="0 0 0"
        rpy="0 0 0" />
      <geometry>
        <mesh
          filename="package://TCB610_06N_urdf/meshes/tl_robot_link1.STL" />
      </geometry>
      <material
        name="">
        <color
          rgba="1 1 1 1" />
      </material>
    </visual>
    <collision>
      <origin
        xyz="0 0 0"
        rpy="0 0 0" />
      <geometry>
        <mesh
          filename="package://TCB610_06N_urdf/meshes/tl_robot_link1.STL" />
      </geometry>
    </collision>
  </link>
  <joint
    name="tl_robot_joint1"
    type="revolute">
    <origin
      xyz="0 0 0.1305"
      rpy="0 0 0" />
    <parent
      link="tl_robot_link0" />
    <child
      link="tl_robot_link1" />
    <axis
      xyz="0 0 1" />
    <limit
      lower="-3.141592654"
      upper="3.141592654"
      effort="0"
      velocity="0" />
  </joint>
  <link
    name="tl_robot_link2">
    <inertial>
      <origin
        xyz="-3.64948803709113E-06 -0.15878316508675 0.00258163777686799"
        rpy="0 0 0" />
      <mass
        value="0.922466553994291" />
      <inertia
        ixx="0.00326663921530272"
        ixy="-8.08050575635626E-09"
        ixz="-1.47598477607018E-07"
        iyy="0.00102266010722135"
        iyz="-4.44984199306338E-05"
        izz="0.00339452282892035" />
    </inertial>
    <visual>
      <origin
        xyz="0 0 0"
        rpy="0 0 0" />
      <geometry>
        <mesh
          filename="package://TCB610_06N_urdf/meshes/tl_robot_link2.STL" />
      </geometry>
      <material
        name="">
        <color
          rgba="1 1 1 1" />
      </material>
    </visual>
    <collision>
      <origin
        xyz="0 0 0"
        rpy="0 0 0" />
      <geometry>
        <mesh
          filename="package://TCB610_06N_urdf/meshes/tl_robot_link2.STL" />
      </geometry>
    </collision>
  </link>
  <joint
    name="tl_robot_joint2"
    type="revolute">
    <origin
      xyz="0 0.016 0.1315"
      rpy="-1.5708 0 0" />
    <parent
      link="tl_robot_link1" />
    <child
      link="tl_robot_link2" />
    <axis
      xyz="0 0 -1" />
    <limit
      lower="-2.35619449"
      upper="2.35619449"
      effort="0"
      velocity="0" />
  </joint>
  <link
    name="tl_robot_link3">
    <inertial>
      <origin
        xyz="2.78354237109954E-06 0.0694960867121006 0.00637377402709792"
        rpy="0 0 0" />
      <mass
        value="0.396498595803028" />
      <inertia
        ixx="0.00137497380584233"
        ixy="7.68580314688229E-08"
        ixz="2.54610387073722E-08"
        iyy="0.000357925421554553"
        iyz="0.000211759769095163"
        izz="0.00141757729346042" />
    </inertial>
    <visual>
      <origin
        xyz="0 0 0"
        rpy="0 0 0" />
      <geometry>
        <mesh
          filename="package://TCB610_06N_urdf/meshes/tl_robot_link3.STL" />
      </geometry>
      <material
        name="">
        <color
          rgba="1 1 1 1" />
      </material>
    </visual>
    <collision>
      <origin
        xyz="0 0 0"
        rpy="0 0 0" />
      <geometry>
        <mesh
          filename="package://TCB610_06N_urdf/meshes/tl_robot_link3.STL" />
      </geometry>
    </collision>
  </link>
  <joint
    name="tl_robot_joint3"
    type="revolute">
    <origin
      xyz="0 -0.3205 -0.0295"
      rpy="-3.14 0 1.5708" />
    <parent
      link="tl_robot_link2" />
    <child
      link="tl_robot_link3" />
    <axis
      xyz="0 0 1" />
    <limit
      lower="-0.959931089"
      upper="4.101523742"
      effort="0"
      velocity="0" />
  </joint>
  <link
    name="tl_robot_link4">
    <inertial>
      <origin
        xyz="-3.40933814129099E-06 -0.0133244789122422 0.0587132278152935"
        rpy="0 0 0" />
      <mass
        value="0.244288838248205" />
      <inertia
        ixx="0.000507361499420707"
        ixy="3.14094200860272E-08"
        ixz="-1.10052697249875E-07"
        iyy="0.000522024117409157"
        iyz="8.94126964826422E-05"
        izz="0.00020297105617683" />
    </inertial>
    <visual>
      <origin
        xyz="0 0 0"
        rpy="0 0 0" />
      <geometry>
        <mesh
          filename="package://TCB610_06N_urdf/meshes/tl_robot_link4.STL" />
      </geometry>
      <material
        name="">
        <color
          rgba="1 1 1 1" />
      </material>
    </visual>
    <collision>
      <origin
        xyz="0 0 0"
        rpy="0 0 0" />
      <geometry>
        <mesh
          filename="package://TCB610_06N_urdf/meshes/tl_robot_link4.STL" />
      </geometry>
    </collision>
  </link>
  <joint
    name="tl_robot_joint4"
    type="revolute">
    <origin
      xyz="0 0.1745 -0.0135"
      rpy="-1.5708 0 0" />
    <parent
      link="tl_robot_link3" />
    <child
      link="tl_robot_link4" />
    <axis
      xyz="0 0 1" />
    <limit
      lower="-3.141592654"
      upper="3.141592654"
      effort="0"
      velocity="0" />
  </joint>
  <link
    name="tl_robot_link5">
    <inertial>
      <origin
        xyz="-1.40320481653003E-05 -0.0434236898124816 0.00052679877060258"
        rpy="0 0 0" />
      <mass
        value="0.248665741580514" />
      <inertia
        ixx="0.000435366365640956"
        ixy="1.02578029161429E-07"
        ixz="3.83958961826191E-08"
        iyy="0.000223309836077531"
        iyz="-9.15144352364642E-05"
        izz="0.000440491062715861" />
    </inertial>
    <visual>
      <origin
        xyz="0 0 0"
        rpy="0 0 0" />
      <geometry>
        <mesh
          filename="package://TCB610_06N_urdf/meshes/tl_robot_link5.STL" />
      </geometry>
      <material
        name="">
        <color
          rgba="0.568627450980392 0.596078431372549 0.623529411764706 1" />
      </material>
    </visual>
    <collision>
      <origin
        xyz="0 0 0"
        rpy="0 0 0" />
      <geometry>
        <mesh
          filename="package://TCB610_06N_urdf/meshes/tl_robot_link5.STL" />
      </geometry>
    </collision>
  </link>
  <joint
    name="tl_robot_joint5"
    type="revolute">
    <origin
      xyz="0 0.0145 0.105"
      rpy="-1.5708 1.5708 0" />
    <parent
      link="tl_robot_link4" />
    <child
      link="tl_robot_link5" />
    <axis
      xyz="0 0 1" />
    <limit
      lower="-3.752457892"
      upper="0.610865238"
      effort="0"
      velocity="0" />
  </joint>
  <link
    name="tl_robot_link6">
    <inertial>
      <origin
        xyz="8.18734378994135E-06 9.1246482065654E-05 0.0267686825888341"
        rpy="0 0 0" />
      <mass
        value="0.222487041141641" />
      <inertia
        ixx="0.000135311205902358"
        ixy="-5.82503171377999E-08"
        ixz="-1.88841459723531E-09"
        iyy="0.000134459672909182"
        iyz="-1.23915005752652E-08"
        izz="0.000181050255328463" />
    </inertial>
    <visual>
      <origin
        xyz="0 0 0"
        rpy="0 0 0" />
      <geometry>
        <mesh
          filename="package://TCB610_06N_urdf/meshes/tl_robot_link6.STL" />
      </geometry>
      <material
        name="">
        <color
          rgba="0.898039215686275 0.917647058823529 0.929411764705882 1" />
      </material>
    </visual>
    <collision>
      <origin
        xyz="0 0 0"
        rpy="0 0 0" />
      <geometry>
        <mesh
          filename="package://TCB610_06N_urdf/meshes/tl_robot_link6.STL" />
      </geometry>
    </collision>
  </link>
  <joint
    name="tl_robot_joint6"
    type="revolute">
    <origin
      xyz="0 -0.1145 -0.0145"
      rpy="1.5708 0 0" />
    <parent
      link="tl_robot_link5" />
    <child
      link="tl_robot_link6" />
    <axis
      xyz="0 0 1" />
    <limit
      lower="-3.141592654"
      upper="3.141592654"
      effort="0"
      velocity="0" />
  </joint>

  <!-- 修正末端180度偏差的虚拟关节和连杆 -->
  <joint
      name="tl_robot_joint_end"
      type="fixed">
      <origin
          xyz="0 0 0"
          rpy="0 0 -3.141592654" />  <!-- 绕Z轴旋转180度修正 -->
      <parent
          link="tl_robot_link6" />
      <child
          link="tl_robot_link_end" />
      <axis
          xyz="0 0 1" />
  </joint>

  <link
      name="tl_robot_link_end">
      <inertial>
          <origin
              xyz="0 0 0"
              rpy="0 0 0" />
          <mass
              value="0.001" />
          <inertia
              ixx="1e-6"
              ixy="0"
              ixz="0"
              iyy="1e-6"
              iyz="0"
              izz="1e-6" />
      </inertial>
      <visual>
          <origin
              xyz="0 0 0"
              rpy="0 0 0" />
          <geometry>
              <box size="0.01 0.01 0.01" />  <!-- 小方块用于可视化 -->
          </geometry>
          <material
              name="eef_color">
              <color
                  rgba="1 0 0 0.5" />  <!-- 红色半透明 -->
          </material>
      </visual>
      <collision>
          <origin
              xyz="0 0 0"
              rpy="0 0 0" />
          <geometry>
              <box size="0.001 0.001 0.001" />  <!-- 很小的碰撞体 -->
          </geometry>
      </collision>
  </link>
</robot>
