<?xml version="1.0" encoding="utf-8"?>
<!-- This URDF was automatically created by SolidWorks to URDF Exporter! Originally created by Stephen Brawner (brawner@gmail.com) 
     Commit Version: 1.6.0-1-g15f4949  Build Version: 1.6.7594.29634
     For more information, please see http://wiki.ros.org/sw_urdf_exporter -->
<robot
  name="TCB710_06N_urdf">
<mujoco>
    <compiler meshdir="../meshes/" discardvisual="false"/>
  </mujoco>
  <link
    name="tl_robot_link0">
    <inertial>
      <origin
        xyz="0.00019716 -5.6594E-05 0.037668"
        rpy="0 0 0" />
      <mass
        value="0.7499" />
      <inertia
        ixx="0.0015624"
        ixy="-6.4826E-08"
        ixz="4.2171E-05"
        iyy="0.0014306"
        iyz="-1.474E-07"
        izz="0.0018195" />
    </inertial>
    <visual>
      <origin
        xyz="0 0 0"
        rpy="0 0 0" />
      <geometry>
        <mesh
          filename="package://TCB710_06N_urdf/meshes/tl_robot_link0.STL" />
      </geometry>
      <material
        name="">
        <color
          rgba="0.79216 0.81961 0.93333 1" />
      </material>
    </visual>
    <collision>
      <origin
        xyz="0 0 0"
        rpy="0 0 0" />
      <geometry>
        <mesh
          filename="package://TCB710_06N_urdf/meshes/tl_robot_link0.STL" />
      </geometry>
    </collision>
  </link>
  <link
    name="tl_robot_link1">
    <inertial>
      <origin
        xyz="-3.2217E-06 -0.015124 0.070502"
        rpy="0 0 0" />
      <mass
        value="0.51848" />
      <inertia
        ixx="0.0016711"
        ixy="1.5621E-07"
        ixz="-1.5467E-07"
        iyy="0.001757"
        iyz="0.00026361"
        izz="0.00078448" />
    </inertial>
    <visual>
      <origin
        xyz="0 0 0"
        rpy="0 0 0" />
      <geometry>
        <mesh
          filename="package://TCB710_06N_urdf/meshes/tl_robot_link1.STL" />
      </geometry>
      <material
        name="">
        <color
          rgba="1 1 1 1" />
      </material>
    </visual>
    <collision>
      <origin
        xyz="0 0 0"
        rpy="0 0 0" />
      <geometry>
        <mesh
          filename="package://TCB710_06N_urdf/meshes/tl_robot_link1.STL" />
      </geometry>
    </collision>
  </link>
  <joint
    name="tl_robot_joint1"
    type="revolute">
    <origin
      xyz="0 0 0.1305"
      rpy="0 0 0" />
    <parent
      link="tl_robot_link0" />
    <child
      link="tl_robot_link1" />
    <axis
      xyz="0 0 1" />
    <limit
      lower="-3.141592654"
      upper="3.141592654"
      effort="0"
      velocity="0" />
  </joint>
  <link
    name="tl_robot_link2">
    <inertial>
      <origin
        xyz="-1.2697E-05 -0.066422 0.0045783"
        rpy="0 0 0" />
      <mass
        value="0.45884" />
      <inertia
        ixx="0.0016432"
        ixy="-2.7265E-07"
        ixz="-7.6925E-08"
        iyy="0.00055884"
        iyz="-0.00028299"
        izz="0.0017123" />
    </inertial>
    <visual>
      <origin
        xyz="0 0 0"
        rpy="0 0 0" />
      <geometry>
        <mesh
          filename="package://TCB710_06N_urdf/meshes/tl_robot_link2.STL" />
      </geometry>
      <material
        name="">
        <color
          rgba="1 1 1 1" />
      </material>
    </visual>
    <collision>
      <origin
        xyz="0 0 0"
        rpy="0 0 0" />
      <geometry>
        <mesh
          filename="package://TCB710_06N_urdf/meshes/tl_robot_link2.STL" />
      </geometry>
    </collision>
  </link>
  <joint
    name="tl_robot_joint2"
    type="revolute">
    <origin
      xyz="0 0.016 0.1315"
      rpy="-1.5708 0 0" />
    <parent
      link="tl_robot_link1" />
    <child
      link="tl_robot_link2" />
    <axis
      xyz="0 0 1" />
    <limit
      lower="-2.35619449"
      upper="2.35619449"
      effort="0"
      velocity="0" />
  </joint>
  <link
    name="tl_robot_link3">
    <inertial>
      <origin
        xyz="5.3045E-06 0.016606 0.08269"
        rpy="0 0 0" />
      <mass
        value="0.46363" />
      <inertia
        ixx="0.0016235"
        ixy="-7.0673E-08"
        ixz="-2.6457E-07"
        iyy="0.0016823"
        iyz="-0.0002385"
        izz="0.00046382" />
    </inertial>
    <visual>
      <origin
        xyz="0 0 0"
        rpy="0 0 0" />
      <geometry>
        <mesh
          filename="package://TCB710_06N_urdf/meshes/tl_robot_link3.STL" />
      </geometry>
      <material
        name="">
        <color
          rgba="0.56863 0.59608 0.62353 1" />
      </material>
    </visual>
    <collision>
      <origin
        xyz="0 0 0"
        rpy="0 0 0" />
      <geometry>
        <mesh
          filename="package://TCB710_06N_urdf/meshes/tl_robot_link3.STL" />
      </geometry>
    </collision>
  </link>
  <joint
    name="tl_robot_joint3"
    type="revolute">
    <origin
      xyz="0 -0.1675 -0.016"
      rpy="1.5708 0 0" />
    <parent
      link="tl_robot_link2" />
    <child
      link="tl_robot_link3" />
    <axis
      xyz="0 0 1" />
    <limit
      lower="-3.141592654"
      upper="3.141592654"
      effort="0"
      velocity="0" />
  </joint>
  <link
    name="tl_robot_link4">
    <inertial>
      <origin
        xyz="2.78354237109905E-06 0.0694960867121007 0.00637377402709792"
        rpy="0 0 0" />
      <mass
        value="0.396498595803027" />
      <inertia
        ixx="0.00137497380584233"
        ixy="7.68580314688507E-08"
        ixz="2.5461038707363E-08"
        iyy="0.000357925421554553"
        iyz="0.000211759769095163"
        izz="0.00141757729346042" />
    </inertial>
    <visual>
      <origin
        xyz="0 0 0"
        rpy="0 0 0" />
      <geometry>
        <mesh
          filename="package://TCB710_06N_urdf/meshes/tl_robot_link4.STL" />
      </geometry>
      <material
        name="">
        <color
          rgba="1 1 1 1" />
      </material>
    </visual>
    <collision>
      <origin
        xyz="0 0 0"
        rpy="0 0 0" />
      <geometry>
        <mesh
          filename="package://TCB710_06N_urdf/meshes/tl_robot_link4.STL" />
      </geometry>
    </collision>
  </link>
  <joint
    name="tl_robot_joint4"
    type="revolute">
    <origin
      xyz="0 -0.0135 0.153"
      rpy="1.5708 0 0" />
    <parent
      link="tl_robot_link3" />
    <child
      link="tl_robot_link4" />
    <axis
      xyz="0 0 -1" />
    <limit
      lower="-2.35619449"
      upper="2.35619449"
      effort="0"
      velocity="0" />
  </joint>
  <link
    name="tl_robot_link5">
    <inertial>
      <origin
        xyz="-3.4093E-06 -0.013324 0.058713"
        rpy="0 0 0" />
      <mass
        value="0.24429" />
      <inertia
        ixx="0.00050736"
        ixy="-3.1473E-09"
        ixz="-1.1005E-07"
        iyy="0.00052202"
        iyz="8.9413E-05"
        izz="0.00020297" />
    </inertial>
    <visual>
      <origin
        xyz="0 0 0"
        rpy="0 0 0" />
      <geometry>
        <mesh
          filename="package://TCB710_06N_urdf/meshes/tl_robot_link5.STL" />
      </geometry>
      <material
        name="">
        <color
          rgba="1 1 1 1" />
      </material>
    </visual>
    <collision>
      <origin
        xyz="0 0 0"
        rpy="0 0 0" />
      <geometry>
        <mesh
          filename="package://TCB710_06N_urdf/meshes/tl_robot_link5.STL" />
      </geometry>
    </collision>
  </link>
  <joint
    name="tl_robot_joint5"
    type="revolute">
    <origin
      xyz="0 0.1745 -0.0135"
      rpy="-1.5708 0 0" />
    <parent
      link="tl_robot_link4" />
    <child
      link="tl_robot_link5" />
    <axis
      xyz="0 0 1" />
    <limit
      lower="-3.141592654"
      upper="3.141592654"
      effort="0"
      velocity="0" />
  </joint>
  <link
    name="tl_robot_link6">
    <inertial>
      <origin
        xyz="-1.4032E-05 -0.043424 0.0005268"
        rpy="0 0 0" />
      <mass
        value="0.24867" />
      <inertia
        ixx="0.00043537"
        ixy="1.0258E-07"
        ixz="3.8396E-08"
        iyy="0.00022331"
        iyz="-9.1514E-05"
        izz="0.00044049" />
    </inertial>
    <visual>
      <origin
        xyz="0 0 0"
        rpy="0 0 0" />
      <geometry>
        <mesh
          filename="package://TCB710_06N_urdf/meshes/tl_robot_link6.STL" />
      </geometry>
      <material
        name="">
        <color
          rgba="0.56863 0.59608 0.62353 1" />
      </material>
    </visual>
    <collision>
      <origin
        xyz="0 0 0"
        rpy="0 0 0" />
      <geometry>
        <mesh
          filename="package://TCB710_06N_urdf/meshes/tl_robot_link6.STL" />
      </geometry>
    </collision>
  </link>
  <joint
    name="tl_robot_joint6"
    type="revolute">
    <origin
      xyz="0 0.0145 0.105"
      rpy="-1.5708 0 0" />
    <parent
      link="tl_robot_link5" />
    <child
      link="tl_robot_link6" />
    <axis
      xyz="0 0 1" />
    <limit
      lower="-2.35619449"
      upper="2.35619449"
      effort="0"
      velocity="0" />
  </joint>
  <link
    name="tl_robot_link7">
    <inertial>
      <origin
        xyz="8.1873E-06 9.1246E-05 0.026769"
        rpy="0 0 0" />
      <mass
        value="0.22249" />
      <inertia
        ixx="0.00013531"
        ixy="-5.825E-08"
        ixz="-1.8884E-09"
        iyy="0.00013446"
        iyz="-1.2392E-08"
        izz="0.00018105" />
    </inertial>
    <visual>
      <origin
        xyz="0 0 0"
        rpy="0 0 0" />
      <geometry>
        <mesh
          filename="package://TCB710_06N_urdf/meshes/tl_robot_link7.STL" />
      </geometry>
      <material
        name="">
        <color
          rgba="0.89804 0.91765 0.92941 1" />
      </material>
    </visual>
    <collision>
      <origin
        xyz="0 0 0"
        rpy="0 0 0" />
      <geometry>
        <mesh
          filename="package://TCB710_06N_urdf/meshes/tl_robot_link7.STL" />
      </geometry>
    </collision>
  </link>
  <joint
    name="tl_robot_joint7"
    type="revolute">
    <origin
      xyz="0 -0.1145 -0.0145"
      rpy="1.5708 0 0" />
    <parent
      link="tl_robot_link6" />
    <child
      link="tl_robot_link7" />
    <axis
      xyz="0 0 1" />
    <limit
      lower="-3.141592654"
      upper="3.141592654"
      effort="0"
      velocity="0" />
  </joint>
  
  <!-- 修正末端180度偏差的虚拟关节和连杆 -->
  <joint
      name="tl_robot_joint_end"
      type="fixed">
      <origin
          xyz="0 0 0"
          rpy="0 0 -3.141592654" />  <!-- 绕Z轴旋转180度修正 -->
      <parent
          link="tl_robot_link7" />
      <child
          link="tl_robot_link_end" />
      <axis
          xyz="0 0 1" />
  </joint>

  <link
      name="tl_robot_link_end">
      <inertial>
          <origin
              xyz="0 0 0"
              rpy="0 0 0" />
          <mass
              value="0.001" />
          <inertia
              ixx="1e-6"
              ixy="0"
              ixz="0"
              iyy="1e-6"
              iyz="0"
              izz="1e-6" />
      </inertial>
      <visual>
          <origin
              xyz="0 0 0"
              rpy="0 0 0" />
          <geometry>
              <box size="0.01 0.01 0.01" />  <!-- 小方块用于可视化 -->
          </geometry>
          <material
              name="eef_color">
              <color
                  rgba="1 0 0 0.5" />  <!-- 红色半透明 -->
          </material>
      </visual>
      <collision>
          <origin
              xyz="0 0 0"
              rpy="0 0 0" />
          <geometry>
              <box size="0.001 0.001 0.001" />  <!-- 很小的碰撞体 -->
          </geometry>
      </collision>
  </link>

</robot>